import { render, screen } from '@testing-library/react'
import { describe, it, expect, beforeAll, afterAll, vi } from 'vitest'
import { ErrorBoundary } from '../ErrorBoundary'

// Mock component that throws an error
const ThrowError = ({ shouldThrow }: { shouldThrow: boolean }) => {
  if (shouldThrow) {
    throw new Error('Test error')
  }
  return <div>No error</div>
}

describe('ErrorBoundary', () => {
  // Suppress console.error for these tests
  const originalError = console.error
  beforeAll(() => {
    console.error = vi.fn()
  })
  afterAll(() => {
    console.error = originalError
  })

  it('renders children when there is no error', () => {
    render(
      <ErrorBoundary>
        <ThrowError shouldThrow={false} />
      </ErrorBoundary>
    )

    expect(screen.getByText('No error')).toBeInTheDocument()
  })

  it('renders error UI when there is an error', () => {
    render(
      <ErrorBoundary>
        <ThrowError shouldThrow={true} />
      </ErrorBoundary>
    )

    expect(screen.getByText('⚠️ Something went wrong')).toBeInTheDocument()
    expect(screen.getByText('We encountered an unexpected error. Please try refreshing the page.')).toBeInTheDocument()
    expect(screen.getByText('Refresh Page')).toBeInTheDocument()
  })

  it('renders custom fallback when provided', () => {
    const customFallback = <div>Custom error message</div>

    render(
      <ErrorBoundary fallback={customFallback}>
        <ThrowError shouldThrow={true} />
      </ErrorBoundary>
    )

    expect(screen.getByText('Custom error message')).toBeInTheDocument()
    expect(screen.queryByText('⚠️ Something went wrong')).not.toBeInTheDocument()
  })
})
